<?xml version="1.0" encoding="utf-8"?>
<!-- This URDF was automatically created by SolidWorks to URDF Exporter! Originally created by Stephen Brawner (brawner@gmail.com) 
     Commit Version: 1.6.0-1-g15f4949  Build Version: 1.6.7594.29634
     For more information, please see http://wiki.ros.org/sw_urdf_exporter -->
<robot
  name="dynamo_skltn">
    <!--<link
    name="world">
      <origin
        xyz="0 0 0"
        rpy="0 0 0" />
  </link>
    <joint
    name="Joint"
    type="fixed">
    <origin
      xyz="0 0 0.355"
      rpy="0 0 0" />
    <parent
      link="world" />
    <child
      link="base_link" />
    <axis
      xyz="0 0 0" />
  </joint> -->
  <link
    name="base_link">
    <inertial>
      <origin
        xyz="6.66133814775094E-16 -1.0769163338864E-14 -0.0100000000000001"
        rpy="0 0 0" />
      <mass
        value="0.307410573676368" />
      <inertia
        ixx="0.00180218659293748"
        ixy="-5.9244660704518E-18"
        ixz="-3.37763309342311E-20"
        iyy="0.00264075287927376"
        iyz="-3.09465764048452E-20"
        izz="0.00442270513895884" />
    </inertial>
    <visual>
      <origin
        xyz="0 0 0"
        rpy="0 0 0" />
      <geometry>
        <mesh
          filename="package://dynamo_skltn/meshes/base_link.STL" />
      </geometry>
      <material
        name="">
        <color
          rgba="0.792156862745098 0.819607843137255 0.933333333333333 1" />
      </material>
    </visual>
    <collision>
      <origin
        xyz="0 0 0"
        rpy="0 0 0" />
      <geometry>
        <mesh
          filename="package://dynamo_skltn/meshes/base_link.STL" />
      </geometry>
    </collision>
  </link>
  <link
    name="LF1">
    <inertial>
      <origin
        xyz="-0.018784210212979 -1.01030295240889E-14 -0.0143997700963781"
        rpy="0 0 0" />
      <mass
        value="0.0202816811678385" />
      <inertia
        ixx="1.42596288638287E-06"
        ixy="8.08885241524575E-23"
        ixz="-1.77006138466586E-07"
        iyy="3.47408088989554E-06"
        iyz="-1.33359464788894E-22"
        izz="3.35153539523793E-06" />
    </inertial>
    <visual>
      <origin
        xyz="0 0 0"
        rpy="0 0 0" />
      <geometry>
        <mesh
          filename="package://dynamo_skltn/meshes/LF1.STL" />
      </geometry>
      <material
        name="">
        <color
          rgba="0.792156862745098 0.819607843137255 0.933333333333333 1" />
      </material>
    </visual>
    <collision>
      <origin
        xyz="0 0 0"
        rpy="0 0 0" />
      <geometry>
        <mesh
          filename="package://dynamo_skltn/meshes/LF1.STL" />
      </geometry>
    </collision>
  </link>
  <joint
    name="LFJ1"
    type="revolute">
    <origin
      xyz="0.1285 0.075 -0.01"
      rpy="1.5708 0 -1.5708" />
    <parent
      link="base_link" />
    <child
      link="LF1" />
    <axis
      xyz="0 0 1" />
    <limit
      lower="-1.57"
      upper="1.57"
      effort="50"
      velocity="2" />
    <dynamics damping="0.1" friction="0.0"/>
  </joint>
  <link
    name="LF2">
    <inertial>
      <origin
        xyz="0.0850000000000102 0 0.00999999999999998"
        rpy="0 0 0" />
      <mass
        value="0.144010087007031" />
      <inertia
        ixx="1.52724036277132E-05"
        ixy="6.68463311186397E-21"
        ixz="-4.79574330687221E-20"
        iyy="0.000456019282253513"
        iyz="-3.80708743488964E-22"
        izz="0.000461691013414091" />
    </inertial>
    <visual>
      <origin
        xyz="0 0 0"
        rpy="0 0 0" />
      <geometry>
        <mesh
          filename="package://dynamo_skltn/meshes/LF2.STL" />
      </geometry>
      <material
        name="">
        <color
          rgba="0.792156862745098 0.819607843137255 0.933333333333333 1" />
      </material>
    </visual>
    <collision>
      <origin
        xyz="0 0 0"
        rpy="0 0 0" />
      <geometry>
        <mesh
          filename="package://dynamo_skltn/meshes/LF2.STL" />
      </geometry>
    </collision>
  </link>
  <joint
    name="LFJ2"
    type="revolute">
    <origin
      xyz="-0.04 0 -0.015"
      rpy="1.5708 0 -1.5708" />
    <parent
      link="LF1" />
    <child
      link="LF2" />
    <axis
      xyz="0 0 -1" />
    <limit
      lower="-1.57"
      upper="1.57"
      effort="50"
      velocity="2" />
    <dynamics damping="0.1" friction="0.0"/>
  </joint>
  <link
    name="LF3">
    <inertial>
      <origin
        xyz="0.0850000000000101 0 0.00999999999999998"
        rpy="0 0 0" />
      <mass
        value="0.144010087007031" />
      <inertia
        ixx="1.52724036277132E-05"
        ixy="6.96869005968292E-21"
        ixz="-2.34998390655045E-20"
        iyy="0.000456019282253513"
        iyz="-4.87410026043126E-22"
        izz="0.00046169101341409" />
    </inertial>
    <visual>
      <origin
        xyz="0 0 0"
        rpy="0 0 0" />
      <geometry>
        <mesh
          filename="package://dynamo_skltn/meshes/LF3.STL" />
      </geometry>
      <material
        name="">
        <color
          rgba="0.792156862745098 0.819607843137255 0.933333333333333 1" />
      </material>
    </visual>
    <collision>
      <origin
        xyz="0 0 0"
        rpy="0 0 0" />
      <geometry>
        <mesh
          filename="package://dynamo_skltn/meshes/LF3.STL" />
      </geometry>
    </collision>
  </link>
  <joint
    name="LFJ3"
    type="revolute">
    <origin
      xyz="0.17 0 0.02"
      rpy="0 0 0" />
    <parent
      link="LF2" />
    <child
      link="LF3" />
    <axis
      xyz="0 0 -1" />
    <limit
      lower="-1.57"
      upper="2.7"
      effort="50"
      velocity="1" />
    <dynamics damping="0.1" friction="0.0"/>
  </joint>
  <link
    name="LB1">
    <inertial>
      <origin
        xyz="-0.0187842102129788 -9.99200722162641E-15 0.0143997700963782"
        rpy="0 0 0" />
      <mass
        value="0.0202816811678385" />
      <inertia
        ixx="1.42596288638287E-06"
        ixy="-1.30959961592588E-22"
        ixz="1.77006138466586E-07"
        iyy="3.47408088989554E-06"
        iyz="-1.76560837638848E-23"
        izz="3.35153539523793E-06" />
    </inertial>
    <visual>
      <origin
        xyz="0 0 0"
        rpy="0 0 0" />
      <geometry>
        <mesh
          filename="package://dynamo_skltn/meshes/LB1.STL" />
      </geometry>
      <material
        name="">
        <color
          rgba="0.792156862745098 0.819607843137255 0.933333333333333 1" />
      </material>
    </visual>
    <collision>
      <origin
        xyz="0 0 0"
        rpy="0 0 0" />
      <geometry>
        <mesh
          filename="package://dynamo_skltn/meshes/LB1.STL" />
      </geometry>
    </collision>
  </link>
  <joint
    name="LBJ1"
    type="revolute">
    <origin
      xyz="-0.1285 0.075 -0.01"
      rpy="1.5708 0 -1.5708" />
    <parent
      link="base_link" />
    <child
      link="LB1" />
    <axis
      xyz="0 0 1" />
    <limit
      lower="-1.57"
      upper="1.57"
      effort="50"
      velocity="2" />
    <dynamics damping="0.1" friction="0.0"/>
  </joint>
  <link
    name="LB2">
    <inertial>
      <origin
        xyz="0.0850000000000102 0 0.00999999999999995"
        rpy="0 0 0" />
      <mass
        value="0.144010087007031" />
      <inertia
        ixx="1.52724036277132E-05"
        ixy="-1.74229305106629E-21"
        ixz="3.85187512524854E-21"
        iyy="0.000456019282253512"
        iyz="-2.61809605891918E-22"
        izz="0.00046169101341409" />
    </inertial>
    <visual>
      <origin
        xyz="0 0 0"
        rpy="0 0 0" />
      <geometry>
        <mesh
          filename="package://dynamo_skltn/meshes/LB2.STL" />
      </geometry>
      <material
        name="">
        <color
          rgba="0.792156862745098 0.819607843137255 0.933333333333333 1" />
      </material>
    </visual>
    <collision>
      <origin
        xyz="0 0 0"
        rpy="0 0 0" />
      <geometry>
        <mesh
          filename="package://dynamo_skltn/meshes/LB2.STL" />
      </geometry>
    </collision>
  </link>
  <joint
    name="LBJ2"
    type="revolute">
    <origin
      xyz="-0.04 0 0.015"
      rpy="1.5707963267949 0 -1.5707963267949" />
    <parent
      link="LB1" />
    <child
      link="LB2" />
    <axis
      xyz="0 0 -1" />
    <limit
      lower="-1.57"
      upper="1.57"
      effort="50"
      velocity="2" />
    <dynamics damping="0.1" friction="0.0"/>
  </joint>
  <link
    name="LB3">
    <inertial>
      <origin
        xyz="0.0850000000000102 1.38777878078145E-17 0.01"
        rpy="0 0 0" />
      <mass
        value="0.144010087007031" />
      <inertia
        ixx="1.52724036277132E-05"
        ixy="-4.89227988199986E-21"
        ixz="-5.96947954866902E-21"
        iyy="0.000456019282253512"
        iyz="4.54227014519487E-23"
        izz="0.00046169101341409" />
    </inertial>
    <visual>
      <origin
        xyz="0 0 0"
        rpy="0 0 0" />
      <geometry>
        <mesh
          filename="package://dynamo_skltn/meshes/LB3.STL" />
      </geometry>
      <material
        name="">
        <color
          rgba="0.792156862745098 0.819607843137255 0.933333333333333 1" />
      </material>
    </visual>
    <collision>
      <origin
        xyz="0 0 0"
        rpy="0 0 0" />
      <geometry>
        <mesh
          filename="package://dynamo_skltn/meshes/LB3.STL" />
      </geometry>
    </collision>
  </link>
  <joint
    name="LBJ3"
    type="revolute">
    <origin
      xyz="0.17 0 0.02"
      rpy="0 0 0" />
    <parent
      link="LB2" />
    <child
      link="LB3" />
    <axis
      xyz="0 0 -1" />
    <limit
      lower="-1.57"
      upper="2.7"
      effort="50"
      velocity="2" />
    <dynamics damping="0.1" friction="0.0"/>
  </joint>
  <link
    name="RF1">
    <inertial>
      <origin
        xyz="-0.0187842102129793 1.11022302462516E-16 0.0143997700963782"
        rpy="0 0 0" />
      <mass
        value="0.0202816811678385" />
      <inertia
        ixx="1.42596288638287E-06"
        ixy="3.59859445033248E-22"
        ixz="1.77006138466586E-07"
        iyy="3.47408088989553E-06"
        iyz="-1.48906330019362E-22"
        izz="3.35153539523792E-06" />
    </inertial>
    <visual>
      <origin
        xyz="0 0 0"
        rpy="0 0 0" />
      <geometry>
        <mesh
          filename="package://dynamo_skltn/meshes/RF1.STL" />
      </geometry>
      <material
        name="">
        <color
          rgba="0.792156862745098 0.819607843137255 0.933333333333333 1" />
      </material>
    </visual>
    <collision>
      <origin
        xyz="0 0 0"
        rpy="0 0 0" />
      <geometry>
        <mesh
          filename="package://dynamo_skltn/meshes/RF1.STL" />
      </geometry>
    </collision>
  </link>
  <joint
    name="RFJ1"
    type="revolute">
    <origin
      xyz="0.1285 -0.075 -0.01"
      rpy="1.5708 0 1.5708" />
    <parent
      link="base_link" />
    <child
      link="RF1" />
    <axis
      xyz="0 0 1" />
    <limit
      lower="-1.57"
      upper="1.57"
      effort="50"
      velocity="2" />
    <dynamics damping="0.1" friction="0.0"/>
  </joint>
  <link
    name="RF2">
    <inertial>
      <origin
        xyz="0.085 0 0.01"
        rpy="0 0 0" />
      <mass
        value="0.144010087007031" />
      <inertia
        ixx="1.52724036277132E-05"
        ixy="-1.10656038486338E-20"
        ixz="3.76166718240562E-20"
        iyy="0.000456019282253512"
        iyz="-1.17287133715646E-22"
        izz="0.00046169101341409" />
    </inertial>
    <visual>
      <origin
        xyz="0 0 0"
        rpy="0 0 0" />
      <geometry>
        <mesh
          filename="package://dynamo_skltn/meshes/RF2.STL" />
      </geometry>
      <material
        name="">
        <color
          rgba="0.792156862745098 0.819607843137255 0.933333333333333 1" />
      </material>
    </visual>
    <collision>
      <origin
        xyz="0 0 0"
        rpy="0 0 0" />
      <geometry>
        <mesh
          filename="package://dynamo_skltn/meshes/RF2.STL" />
      </geometry>
    </collision>
  </link>
  <joint
    name="RFJ2"
    type="revolute">
    <origin
      xyz="-0.04 0 0.0149999999999998"
      rpy="1.5707963267949 0 -1.5707963267949" />
    <parent
      link="RF1" />
    <child
      link="RF2" />
    <axis
      xyz="0 0 1" />
    <limit
      lower="-1.57"
      upper="1.57"
      effort="50"
      velocity="2" />
    <dynamics damping="0.1" friction="0.0"/>
  </joint>
  <link
    name="RF3">
    <inertial>
      <origin
        xyz="0.085 5.55111512312578E-17 0.01"
        rpy="0 0 0" />
      <mass
        value="0.144010087007031" />
      <inertia
        ixx="1.52724036277132E-05"
        ixy="-1.49048345626674E-19"
        ixz="4.58508014330682E-21"
        iyy="0.000456019282253513"
        iyz="-3.37763465288728E-22"
        izz="0.000461691013414091" />
    </inertial>
    <visual>
      <origin
        xyz="0 0 0"
        rpy="0 0 0" />
      <geometry>
        <mesh
          filename="package://dynamo_skltn/meshes/RF3.STL" />
      </geometry>
      <material
        name="">
        <color
          rgba="0.792156862745098 0.819607843137255 0.933333333333333 1" />
      </material>
    </visual>
    <collision>
      <origin
        xyz="0 0 0"
        rpy="0 0 0" />
      <geometry>
        <mesh
          filename="package://dynamo_skltn/meshes/RF3.STL" />
      </geometry>
    </collision>
  </link>
  <joint
    name="RFJ3"
    type="revolute">
    <origin
      xyz="0.17 0 0.0200000000000002"
      rpy="0 0 0" />
    <parent
      link="RF2" />
    <child
      link="RF3" />
    <axis
      xyz="0 0 1" />
    <limit
      lower="-1.57"
      upper="2.7"
      effort="50"
      velocity="2" />
    <dynamics damping="0.1" friction="0.0"/>
  </joint>
  <link
    name="RB1">
    <inertial>
      <origin
        xyz="-0.018784210212979 0 -0.0143997700963782"
        rpy="0 0 0" />
      <mass
        value="0.0202816811678385" />
      <inertia
        ixx="1.42596288638287E-06"
        ixy="4.46967372118645E-23"
        ixz="-1.77006138466586E-07"
        iyy="3.47408088989554E-06"
        iyz="-1.28185631777766E-22"
        izz="3.35153539523793E-06" />
    </inertial>
    <visual>
      <origin
        xyz="0 0 0"
        rpy="0 0 0" />
      <geometry>
        <mesh
          filename="package://dynamo_skltn/meshes/RB1.STL" />
      </geometry>
      <material
        name="">
        <color
          rgba="0.792156862745098 0.819607843137255 0.933333333333333 1" />
      </material>
    </visual>
    <collision>
      <origin
        xyz="0 0 0"
        rpy="0 0 0" />
      <geometry>
        <mesh
          filename="package://dynamo_skltn/meshes/RB1.STL" />
      </geometry>
    </collision>
  </link>
  <joint
    name="RBJ1"
    type="revolute">
    <origin
      xyz="-0.128500000000002 -0.074999999999994 -0.00999999999997347"
      rpy="1.5707963267949 0 1.5707963267949" />
    <parent
      link="base_link" />
    <child
      link="RB1" />
    <axis
      xyz="0 0 1" />
    <limit
      lower="-1.57"
      upper="1.57"
      effort="50"
      velocity="2" />
    <dynamics damping="0.1" friction="0.0"/>
  </joint>
  <link
    name="RB2">
    <inertial>
      <origin
        xyz="0.085 -6.93889390390723E-17 0.01"
        rpy="0 0 0" />
      <mass
        value="0.144010087007031" />
      <inertia
        ixx="1.52724036277132E-05"
        ixy="-1.03552966848308E-19"
        ixz="3.14317062750219E-21"
        iyy="0.000456019282253513"
        iyz="-1.68012162689126E-22"
        izz="0.000461691013414091" />
    </inertial>
    <visual>
      <origin
        xyz="0 0 0"
        rpy="0 0 0" />
      <geometry>
        <mesh
          filename="package://dynamo_skltn/meshes/RB2.STL" />
      </geometry>
      <material
        name="">
        <color
          rgba="0.792156862745098 0.819607843137255 0.933333333333333 1" />
      </material>
    </visual>
    <collision>
      <origin
        xyz="0 0 0"
        rpy="0 0 0" />
      <geometry>
        <mesh
          filename="package://dynamo_skltn/meshes/RB2.STL" />
      </geometry>
    </collision>
  </link>
  <joint
    name="RBJ2"
    type="revolute">
    <origin
      xyz="-0.04 0 -0.0149999999999999"
      rpy="1.5707963267949 0 -1.5707963267949" />
    <parent
      link="RB1" />
    <child
      link="RB2" />
    <axis
      xyz="0 0 1" />
    <limit
      lower="-1.57"
      upper="1.57"
      effort="50"
      velocity="2" />
    <dynamics damping="0.1" friction="0.0"/>
  </joint>
  <link
    name="RB3">
    <inertial>
      <origin
        xyz="0.085 0 0.0099999999999999"
        rpy="0 0 0" />
      <mass
        value="0.144010087007031" />
      <inertia
        ixx="1.52724036277132E-05"
        ixy="2.49794660925494E-20"
        ixz="6.17015260641853E-20"
        iyy="0.000456019282253512"
        iyz="-5.50090825610768E-22"
        izz="0.00046169101341409" />
    </inertial>
    <visual>
      <origin
        xyz="0 0 0"
        rpy="0 0 0" />
      <geometry>
        <mesh
          filename="package://dynamo_skltn/meshes/RB3.STL" />
      </geometry>
      <material
        name="">
        <color
          rgba="0.792156862745098 0.819607843137255 0.933333333333333 1" />
      </material>
    </visual>
    <collision>
      <origin
        xyz="0 0 0"
        rpy="0 0 0" />
      <geometry>
        <mesh
          filename="package://dynamo_skltn/meshes/RB3.STL" />
      </geometry>
    </collision>
  </link>
  <joint
    name="RBJ3"
    type="revolute">
    <origin
      xyz="0.17 0 0.0200000000000002"
      rpy="0 0 0" />
    <parent
      link="RB2" />
    <child
      link="RB3" />
    <axis
      xyz="0 0 1" />
    <limit
      lower="-1.57"
      upper="2.7"
      effort="50"
      velocity="2" />
    <dynamics damping="0.1" friction="0.0"/>
  </joint>

  <gazebo>
  <plugin name="gazebo_ros_control" filename="libgazebo_ros_control.so">
    <robotNamespace>/dynamo</robotNamespace>
    <robotSimType>gazebo_ros_control/DefaultRobotHWSim</robotSimType>
  </plugin>
  </gazebo>

  <transmission name="tran1">
    <type>transmission_interface/SimpleTransmission</type>
    <actuator name="motor1">
      <mechanicalReduction>1</mechanicalReduction>
      <hardwareInterface>EffortJointInterface</hardwareInterface>
    </actuator>
    <joint name="LFJ1">
      <hardwareInterface>EffortJointInterface</hardwareInterface>
    </joint>
  </transmission>
  <transmission name="tran2">
    <type>transmission_interface/SimpleTransmission</type>
    <actuator name="motor2">
      <hardwareInterface>EffortJointInterface</hardwareInterface>
      <mechanicalReduction>1</mechanicalReduction>
    </actuator>
    <joint name="LFJ2">
      <hardwareInterface>EffortJointInterface</hardwareInterface>
    </joint>
  </transmission>
    <transmission name="tran3">
    <type>transmission_interface/SimpleTransmission</type>
    <actuator name="motor3">
      <hardwareInterface>EffortJointInterface</hardwareInterface>
      <mechanicalReduction>1</mechanicalReduction>
    </actuator>
    <joint name="LFJ3">
      <hardwareInterface>EffortJointInterface</hardwareInterface>
    </joint>
  </transmission>
    <transmission name="tran4">
    <type>transmission_interface/SimpleTransmission</type>
    <actuator name="motor4">
      <hardwareInterface>EffortJointInterface</hardwareInterface>
      <mechanicalReduction>1</mechanicalReduction>
    </actuator>
    <joint name="LBJ1">
      <hardwareInterface>EffortJointInterface</hardwareInterface>
    </joint>
  </transmission>
    <transmission name="tran5">
    <type>transmission_interface/SimpleTransmission</type>
    <actuator name="motor5">
      <hardwareInterface>EffortJointInterface</hardwareInterface>
      <mechanicalReduction>1</mechanicalReduction>
    </actuator>
    <joint name="LBJ2">
      <hardwareInterface>EffortJointInterface</hardwareInterface>
    </joint>
  </transmission>
    <transmission name="tran6">
    <type>transmission_interface/SimpleTransmission</type>
    <actuator name="motor6">
      <hardwareInterface>EffortJointInterface</hardwareInterface>
      <mechanicalReduction>1</mechanicalReduction>
    </actuator>
    <joint name="LBJ3">
      <hardwareInterface>EffortJointInterface</hardwareInterface>
    </joint>
  </transmission>
    <transmission name="tran7">
    <type>transmission_interface/SimpleTransmission</type>
    <actuator name="motor7">
      <hardwareInterface>EffortJointInterface</hardwareInterface>
      <mechanicalReduction>1</mechanicalReduction>
    </actuator>
    <joint name="RFJ1">
      <hardwareInterface>EffortJointInterface</hardwareInterface>
    </joint>
  </transmission>
    <transmission name="tran8">
    <type>transmission_interface/SimpleTransmission</type>
    <actuator name="motor8">
      <hardwareInterface>EffortJointInterface</hardwareInterface>
      <mechanicalReduction>1</mechanicalReduction>
    </actuator>
    <joint name="RFJ2">
      <hardwareInterface>EffortJointInterface</hardwareInterface>
    </joint>
  </transmission>
    <transmission name="tran9">
    <type>transmission_interface/SimpleTransmission</type>
    <actuator name="motor9">
      <hardwareInterface>EffortJointInterface</hardwareInterface>
      <mechanicalReduction>1</mechanicalReduction>
    </actuator>
    <joint name="RFJ3">
      <hardwareInterface>EffortJointInterface</hardwareInterface>
    </joint>
  </transmission>
    <transmission name="tran10">
    <type>transmission_interface/SimpleTransmission</type>
    <actuator name="motor10">
      <hardwareInterface>EffortJointInterface</hardwareInterface>
      <mechanicalReduction>1</mechanicalReduction>
    </actuator>
    <joint name="RBJ1">
      <hardwareInterface>EffortJointInterface</hardwareInterface>
    </joint>
  </transmission>
    <transmission name="tran11">
    <type>transmission_interface/SimpleTransmission</type>
    <actuator name="motor11">
      <hardwareInterface>EffortJointInterface</hardwareInterface>
      <mechanicalReduction>1</mechanicalReduction>
    </actuator>
    <joint name="RBJ2">
      <hardwareInterface>EffortJointInterface</hardwareInterface>
    </joint>
  </transmission>
    <transmission name="tran12">
    <type>transmission_interface/SimpleTransmission</type>
    <actuator name="motor12">
      <hardwareInterface>EffortJointInterface</hardwareInterface>
      <mechanicalReduction>1</mechanicalReduction>
    </actuator>
    <joint name="RBJ3">
      <hardwareInterface>EffortJointInterface</hardwareInterface>
    </joint>
  </transmission>
  
  <gazebo reference="base_link">
      <mu1>0.2</mu1>
      <mu2>0.2</mu2>
      <material>Gazebo/Grey</material>
      <selfCollide>false</selfCollide>
  </gazebo>
  
  <gazebo reference="LF1">
      <mu1>0.2</mu1>
      <mu2>0.2</mu2>
      <material>Gazebo/Grey</material>
      <selfCollide>false</selfCollide>
  </gazebo>
    <gazebo reference="LF2">
      <mu1>0.2</mu1>
      <mu2>0.2</mu2>
      <material>Gazebo/Grey</material>
      <selfCollide>false</selfCollide>
  </gazebo>
    <gazebo reference="LF3">
    <kp>100000000.0</kp>
    <kd>1.0</kd>
    <mu1>9000000</mu1>
    <mu2>9000000</mu2>
    <!--<maxContacts>30</maxContacts>-->
    <fdir1>1 1 0</fdir1>
    <maxVel>1.0</maxVel>
    <minDepth>0.001</minDepth>
    <material>Gazebo/Blue</material>
  </gazebo>
  
  <gazebo reference="LB1">
      <mu1>0.2</mu1>
      <mu2>0.2</mu2>
      <material>Gazebo/Grey</material>
      <selfCollide>false</selfCollide>
  </gazebo>
    <gazebo reference="LB2">
      <mu1>0.2</mu1>
      <mu2>0.2</mu2>
      <material>Gazebo/Grey</material>
      <selfCollide>false</selfCollide>
  </gazebo>
    <gazebo reference="LB3">
    <kp>100000000.0</kp>
    <kd>1.0</kd>
    <mu1>9000000</mu1>
    <mu2>9000000</mu2>
    <!--<maxContacts>30</maxContacts>-->
    <fdir1>1 1 0</fdir1>
    <maxVel>1.0</maxVel>
    <minDepth>0.001</minDepth>
    <material>Gazebo/Blue</material>
  </gazebo>

  <gazebo reference="RF1">
      <mu1>0.2</mu1>
      <mu2>0.2</mu2>
      <material>Gazebo/Grey</material>
      <selfCollide>false</selfCollide>
  </gazebo>
    <gazebo reference="RF2">
      <mu1>0.2</mu1>
      <mu2>0.2</mu2>
      <material>Gazebo/Grey</material>
      <selfCollide>false</selfCollide>
  </gazebo>
    <gazebo reference="RF3">
    <kp>100000000.0</kp>
    <kd>1.0</kd>
    <mu1>9000000</mu1>
    <mu2>9000000</mu2>
    <!--<maxContacts>30</maxContacts>-->
    <fdir1>1 1 0</fdir1>
    <maxVel>1.0</maxVel>
    <minDepth>0.001</minDepth>
    <material>Gazebo/Blue</material>
  </gazebo>

  <gazebo reference="RB1">
      <mu1>0.2</mu1>
      <mu2>0.2</mu2>
      <material>Gazebo/Grey</material>
      <selfCollide>false</selfCollide>
  </gazebo>
    <gazebo reference="RB2">
      <mu1>0.2</mu1>
      <mu2>0.2</mu2>
      <material>Gazebo/Grey</material>
      <selfCollide>false</selfCollide>
  </gazebo>
    <gazebo reference="RB3">
    <kp>100000000.0</kp>
    <kd>1.0</kd>
    <mu1>9000000</mu1>
    <mu2>9000000</mu2>
    <!--<maxContacts>30</maxContacts>-->
    <fdir1>1 1 0</fdir1>
    <maxVel>1.0</maxVel>
    <minDepth>0.001</minDepth>
    <material>Gazebo/Blue</material>
  </gazebo>
</robot>